<?xml version="1.0"?> 
<sdf version='1.7'>
  <world name='default'>
    <light name='sun' type='directional'>
      <cast_shadows>1</cast_shadows>
      <pose>0 0 10 0 -0 0</pose>
      <diffuse>0.8 0.8 0.8 1</diffuse>
      <specular>0.1 0.1 0.1 1</specular>
      <attenuation>
        <range>1000</range>
        <constant>0.9</constant>
        <linear>0.01</linear>
        <quadratic>0.001</quadratic>
      </attenuation>
      <direction>-0.5 0.5 -1</direction>
      <spot>
        <inner_angle>0</inner_angle>
        <outer_angle>0</outer_angle>
        <falloff>0</falloff>
      </spot>
    </light>
    <model name='ground_plane'>
      <static>1</static>
      <link name='link'>
        <collision name='collision'>
          <geometry>
            <plane>
              <normal>0 0 1</normal>
              <size>100 100</size>
            </plane>
          </geometry>
          <surface>
            <friction>
              <ode>
                <mu>1</mu>
                <mu2>1</mu2>
              </ode>
              <torsional>
                <ode/>
              </torsional>
            </friction>
            <contact>
              <ode/>
            </contact>
            <bounce/>
          </surface>
          <max_contacts>10</max_contacts>
        </collision>
        <visual name='visual'>
          <cast_shadows>0</cast_shadows>
          <geometry>
            <plane>
              <normal>0 0 1</normal>
              <size>100 100</size>
            </plane>
          </geometry>
          <material>
            <script>
              <uri>file://media/materials/scripts/gazebo.material</uri>
              <name>Gazebo/Grey</name>
            </script>
          </material>
        </visual>
        <self_collide>0</self_collide>
        <kinematic>0</kinematic>
        <gravity>1</gravity>
        <enable_wind>0</enable_wind>
      </link>
    </model>
    <gravity>0 0 -9.8</gravity>
    <magnetic_field>6e-06 2.3e-05 -4.2e-05</magnetic_field>
    <atmosphere type='adiabatic'/>
    <physics name='default_physics' default='0' type='ode'>
      <max_step_size>0.001</max_step_size>
      <real_time_factor>1</real_time_factor>
      <real_time_update_rate>1000</real_time_update_rate>
    </physics>
    <scene>
      <ambient>0.4 0.4 0.4 1</ambient>
      <background>0.7 0.7 0.7 1</background>
      <shadows>1</shadows>
    </scene>
    <spherical_coordinates>
      <surface_model>EARTH_WGS84</surface_model>
      <latitude_deg>0</latitude_deg>
      <longitude_deg>0</longitude_deg>
      <elevation>0</elevation>
      <heading_deg>0</heading_deg>
    </spherical_coordinates>
    <gui fullscreen='0'>
      <camera name='user_camera'>
        <pose>0 12 12 0 0.8 -1.5708</pose>
        <view_controller>orbit</view_controller>
        <projection_type>perspective</projection_type>
      </camera>
    </gui>
    <wind/>
    <model name='logger1'>
      <link name='logger-chassis'>
        <inertial>
          <pose>0.005952 0 -0.002381 0 -0 0</pose>
          <mass>2.1</mass>
          <inertia>
            <ixx>0.0332188</ixx>
            <ixy>0</ixy>
            <ixz>0.000595238</ixz>
            <iyy>0.0347069</iyy>
            <iyz>0</iyz>
            <izz>0.0640521</izz>
          </inertia>
        </inertial>
        <collision name='logger-chassis_collision'>
          <pose>0 0 0 0 -0 0</pose>
          <geometry>
            <cylinder>
              <length>0.1</length>
              <radius>0.25</radius>
            </cylinder>
          </geometry>
          <surface>
            <contact>
              <ode/>
            </contact>
            <friction>
              <ode>
                <mu>0.5</mu>
                <mu2>0.5</mu2>
              </ode>
              <torsional>
                <ode/>
              </torsional>
            </friction>
            <bounce/>
          </surface>
          <max_contacts>10</max_contacts>
        </collision>
        <collision name='logger-chassis_fixed_joint_lump__logger-caster_collision_1'>
          <pose>0.125 0 -0.05 0 -0 0</pose>
          <geometry>
            <sphere>
              <radius>0.04</radius>
            </sphere>
          </geometry>
          <surface>
            <contact>
              <ode/>
            </contact>
            <friction>
              <ode>
                <mu>0</mu>
                <mu2>0</mu2>
              </ode>
              <torsional>
                <ode/>
              </torsional>
            </friction>
            <bounce/>
          </surface>
          <max_contacts>10</max_contacts>
        </collision>
        <visual name='logger-chassis_visual'>
          <pose>0 0 0 0 -0 0</pose>
          <geometry>
            <cylinder>
              <length>0.1</length>
              <radius>0.25</radius>
            </cylinder>
          </geometry>
          <material>
            <script>
              <name>Gazebo/White</name>
              <uri>file://media/materials/scripts/gazebo.material</uri>
            </script>
          </material>
        </visual>
        <visual name='logger-chassis_fixed_joint_lump__logger-caster_visual_1'>
          <pose>0.125 0 -0.05 0 -0 0</pose>
          <geometry>
            <sphere>
              <radius>0.04</radius>
            </sphere>
          </geometry>
          <material>
            <script>
              <name>Gazebo/Grey</name>
              <uri>file://media/materials/scripts/gazebo.material</uri>
            </script>
          </material>
        </visual>
        <velocity_decay/>
        <gravity>1</gravity>
        <velocity_decay/>
        <self_collide>0</self_collide>
        <enable_wind>0</enable_wind>
        <kinematic>0</kinematic>
      </link>
      <joint name='logger-chassis2hat' type='revolute'>
        <pose relative_to='logger-chassis'>0 0 0.1 0 -0 0</pose>
        <parent>logger-chassis</parent>
        <child>logger-hat</child>
        <axis>
          <xyz>0 0 1</xyz>
          <limit>
            <lower>-1e+16</lower>
            <upper>1e+16</upper>
          </limit>
          <dynamics>
            <spring_reference>0</spring_reference>
            <spring_stiffness>0</spring_stiffness>
          </dynamics>
        </axis>
      </joint>
      <link name='logger-hat'>
        <pose relative_to='logger-chassis2hat'>0 0 0 0 -0 0</pose>
        <inertial>
          <pose>0 0 0.04 0 -0 0</pose>
          <mass>0.5</mass>
          <inertia>
            <ixx>0.000466667</ixx>
            <ixy>0</ixy>
            <ixz>0</ixz>
            <iyy>0.000466667</iyy>
            <iyz>0</iyz>
            <izz>0.0001</izz>
          </inertia>
        </inertial>
        <collision name='logger-hat_collision'>
          <pose>0 0 0 0 -0 0</pose>
          <geometry>
            <cylinder>
              <length>0.1</length>
              <radius>0.02</radius>
            </cylinder>
          </geometry>
          <surface>
            <contact>
              <ode/>
            </contact>
            <friction>
              <ode>
                <mu>0</mu>
                <mu2>0</mu2>
              </ode>
              <torsional>
                <ode/>
              </torsional>
            </friction>
            <bounce/>
          </surface>
          <max_contacts>10</max_contacts>
        </collision>
        <visual name='logger-hat_visual'>
          <pose>0 0 0 0 -0 0</pose>
          <geometry>
            <cylinder>
              <length>0.1</length>
              <radius>0.02</radius>
            </cylinder>
          </geometry>
          <material>
            <script>
              <name>Gazebo/Red</name>
              <uri>file://media/materials/scripts/gazebo.material</uri>
            </script>
          </material>
        </visual>
        <gravity>1</gravity>
        <velocity_decay/>
        <self_collide>0</self_collide>
        <enable_wind>0</enable_wind>
        <kinematic>0</kinematic>
      </link>
      <joint name='logger-chassis2left_wheel' type='revolute'>
        <pose relative_to='logger-chassis'>-0.125 -0.125 0 0 -0 0</pose>
        <parent>logger-chassis</parent>
        <child>logger-left_wheel</child>
        <axis>
          <xyz>0 1 0</xyz>
          <limit>
            <lower>-1e+16</lower>
            <upper>1e+16</upper>
          </limit>
          <dynamics>
            <spring_reference>0</spring_reference>
            <spring_stiffness>0</spring_stiffness>
          </dynamics>
        </axis>
      </joint>
      <link name='logger-left_wheel'>
        <pose relative_to='logger-chassis2left_wheel'>0 0 0 0 -0 0</pose>
        <inertial>
          <pose>0 0 0 1.5708 -0 0</pose>
          <mass>0.5</mass>
          <inertia>
            <ixx>0.00107917</ixx>
            <ixy>0</ixy>
            <ixz>0</ixz>
            <iyy>0.00107917</iyy>
            <iyz>0</iyz>
            <izz>0.002025</izz>
          </inertia>
        </inertial>
        <collision name='logger-left_wheel_collision'>
          <pose>0 0 0 1.5708 -0 0</pose>
          <geometry>
            <cylinder>
              <length>0.04</length>
              <radius>0.09</radius>
            </cylinder>
          </geometry>
          <surface>
            <contact>
              <ode/>
            </contact>
            <friction>
              <ode>
                <mu>0.99</mu>
                <mu2>0.99</mu2>
              </ode>
              <torsional>
                <ode/>
              </torsional>
            </friction>
            <bounce/>
          </surface>
          <max_contacts>10</max_contacts>
        </collision>
        <visual name='logger-left_wheel_visual'>
          <pose>0 0 0 1.5708 -0 0</pose>
          <geometry>
            <cylinder>
              <length>0.04</length>
              <radius>0.09</radius>
            </cylinder>
          </geometry>
          <material>
            <script>
              <name>Gazebo/Wood</name>
              <uri>file://media/materials/scripts/gazebo.material</uri>
            </script>
          </material>
        </visual>
        <gravity>1</gravity>
        <velocity_decay/>
        <self_collide>0</self_collide>
        <enable_wind>0</enable_wind>
        <kinematic>0</kinematic>
      </link>
      <joint name='logger-chassis2right_wheel' type='revolute'>
        <pose relative_to='logger-chassis'>-0.125 0.125 0 0 -0 0</pose>
        <parent>logger-chassis</parent>
        <child>logger-right_wheel</child>
        <axis>
          <xyz>0 1 0</xyz>
          <limit>
            <lower>-1e+16</lower>
            <upper>1e+16</upper>
          </limit>
          <dynamics>
            <spring_reference>0</spring_reference>
            <spring_stiffness>0</spring_stiffness>
          </dynamics>
        </axis>
      </joint>
      <link name='logger-right_wheel'>
        <pose relative_to='logger-chassis2right_wheel'>0 0 0 0 -0 0</pose>
        <inertial>
          <pose>0 0 0 1.5708 -0 0</pose>
          <mass>0.5</mass>
          <inertia>
            <ixx>0.00107917</ixx>
            <ixy>0</ixy>
            <ixz>0</ixz>
            <iyy>0.00107917</iyy>
            <iyz>0</iyz>
            <izz>0.002025</izz>
          </inertia>
        </inertial>
        <collision name='logger-right_wheel_collision'>
          <pose>0 0 0 1.5708 -0 0</pose>
          <geometry>
            <cylinder>
              <length>0.04</length>
              <radius>0.09</radius>
            </cylinder>
          </geometry>
          <surface>
            <contact>
              <ode/>
            </contact>
            <friction>
              <ode>
                <mu>0.99</mu>
                <mu2>0.99</mu2>
              </ode>
              <torsional>
                <ode/>
              </torsional>
            </friction>
            <bounce/>
          </surface>
          <max_contacts>10</max_contacts>
        </collision>
        <visual name='logger-right_wheel_visual'>
          <pose>0 0 0 1.5708 -0 0</pose>
          <geometry>
            <cylinder>
              <length>0.04</length>
              <radius>0.09</radius>
            </cylinder>
          </geometry>
          <material>
            <script>
              <name>Gazebo/Wood</name>
              <uri>file://media/materials/scripts/gazebo.material</uri>
            </script>
          </material>
        </visual>
        <gravity>1</gravity>
        <velocity_decay/>
        <self_collide>0</self_collide>
        <enable_wind>0</enable_wind>
        <kinematic>0</kinematic>
      </link>
      <static>0</static>
      <plugin name='differential_drive_controller' filename='libgazebo_ros_diff_drive.so'>
        <legacyMode>0</legacyMode>
        <alwaysOn>1</alwaysOn>
        <updateRate>100</updateRate>
        <leftJoint>logger-chassis2left_wheel</leftJoint>
        <rightJoint>logger-chassis2right_wheel</rightJoint>
        <wheelSeparation>0.25</wheelSeparation>
        <wheelDiameter>0.18</wheelDiameter>
        <wheelTorque>1</wheelTorque>
        <commandTopic>logger1/cmd_vel</commandTopic>
        <odometryTopic>odom</odometryTopic>
        <odometryFrame>odom</odometryFrame>
        <robotBaseFrame>logger-chassis</robotBaseFrame>
        <robotNamespace>/</robotNamespace>
      </plugin>
      <pose>1 0 0.1 0 -0 1.57</pose>
    </model>
    <model name='logger0'>
      <link name='logger-chassis'>
        <inertial>
          <pose>0.005952 0 -0.002381 0 -0 0</pose>
          <mass>2.1</mass>
          <inertia>
            <ixx>0.0332188</ixx>
            <ixy>0</ixy>
            <ixz>0.000595238</ixz>
            <iyy>0.0347069</iyy>
            <iyz>0</iyz>
            <izz>0.0640521</izz>
          </inertia>
        </inertial>
        <collision name='logger-chassis_collision'>
          <pose>0 0 0 0 -0 0</pose>
          <geometry>
            <cylinder>
              <length>0.1</length>
              <radius>0.25</radius>
            </cylinder>
          </geometry>
          <surface>
            <contact>
              <ode/>
            </contact>
            <friction>
              <ode>
                <mu>0.5</mu>
                <mu2>0.5</mu2>
              </ode>
              <torsional>
                <ode/>
              </torsional>
            </friction>
            <bounce/>
          </surface>
          <max_contacts>10</max_contacts>
        </collision>
        <collision name='logger-chassis_fixed_joint_lump__logger-caster_collision_1'>
          <pose>0.125 0 -0.05 0 -0 0</pose>
          <geometry>
            <sphere>
              <radius>0.04</radius>
            </sphere>
          </geometry>
          <surface>
            <contact>
              <ode/>
            </contact>
            <friction>
              <ode>
                <mu>0</mu>
                <mu2>0</mu2>
              </ode>
              <torsional>
                <ode/>
              </torsional>
            </friction>
            <bounce/>
          </surface>
          <max_contacts>10</max_contacts>
        </collision>
        <visual name='logger-chassis_visual'>
          <pose>0 0 0 0 -0 0</pose>
          <geometry>
            <cylinder>
              <length>0.1</length>
              <radius>0.25</radius>
            </cylinder>
          </geometry>
          <material>
            <script>
              <name>Gazebo/Blue</name>
              <uri>file://media/materials/scripts/gazebo.material</uri>
            </script>
          </material>
        </visual>
        <visual name='logger-chassis_fixed_joint_lump__logger-caster_visual_1'>
          <pose>0.125 0 -0.05 0 -0 0</pose>
          <geometry>
            <sphere>
              <radius>0.04</radius>
            </sphere>
          </geometry>
          <material>
            <script>
              <name>Gazebo/Grey</name>
              <uri>file://media/materials/scripts/gazebo.material</uri>
            </script>
          </material>
        </visual>
        <velocity_decay/>
        <gravity>1</gravity>
        <velocity_decay/>
        <self_collide>0</self_collide>
        <enable_wind>0</enable_wind>
        <kinematic>0</kinematic>
      </link>
      <joint name='logger-chassis2hat' type='revolute'>
        <pose relative_to='logger-chassis'>0 0 0.1 0 -0 0</pose>
        <parent>logger-chassis</parent>
        <child>logger-hat</child>
        <axis>
          <xyz>0 0 1</xyz>
          <limit>
            <lower>-1e+16</lower>
            <upper>1e+16</upper>
          </limit>
          <dynamics>
            <spring_reference>0</spring_reference>
            <spring_stiffness>0</spring_stiffness>
          </dynamics>
        </axis>
      </joint>
      <link name='logger-hat'>
        <pose relative_to='logger-chassis2hat'>0 0 0 0 -0 0</pose>
        <inertial>
          <pose>0 0 0.04 0 -0 0</pose>
          <mass>0.5</mass>
          <inertia>
            <ixx>0.000466667</ixx>
            <ixy>0</ixy>
            <ixz>0</ixz>
            <iyy>0.000466667</iyy>
            <iyz>0</iyz>
            <izz>0.0001</izz>
          </inertia>
        </inertial>
        <collision name='logger-hat_collision'>
          <pose>0 0 0 0 -0 0</pose>
          <geometry>
            <cylinder>
              <length>0.1</length>
              <radius>0.02</radius>
            </cylinder>
          </geometry>
          <surface>
            <contact>
              <ode/>
            </contact>
            <friction>
              <ode>
                <mu>0</mu>
                <mu2>0</mu2>
              </ode>
              <torsional>
                <ode/>
              </torsional>
            </friction>
            <bounce/>
          </surface>
          <max_contacts>10</max_contacts>
        </collision>
        <visual name='logger-hat_visual'>
          <pose>0 0 0 0 -0 0</pose>
          <geometry>
            <cylinder>
              <length>0.1</length>
              <radius>0.02</radius>
            </cylinder>
          </geometry>
          <material>
            <script>
              <name>Gazebo/Red</name>
              <uri>file://media/materials/scripts/gazebo.material</uri>
            </script>
          </material>
        </visual>
        <gravity>1</gravity>
        <velocity_decay/>
        <self_collide>0</self_collide>
        <enable_wind>0</enable_wind>
        <kinematic>0</kinematic>
      </link>
      <joint name='logger-chassis2left_wheel' type='revolute'>
        <pose relative_to='logger-chassis'>-0.125 -0.125 0 0 -0 0</pose>
        <parent>logger-chassis</parent>
        <child>logger-left_wheel</child>
        <axis>
          <xyz>0 1 0</xyz>
          <limit>
            <lower>-1e+16</lower>
            <upper>1e+16</upper>
          </limit>
          <dynamics>
            <spring_reference>0</spring_reference>
            <spring_stiffness>0</spring_stiffness>
          </dynamics>
        </axis>
      </joint>
      <link name='logger-left_wheel'>
        <pose relative_to='logger-chassis2left_wheel'>0 0 0 0 -0 0</pose>
        <inertial>
          <pose>0 0 0 1.5708 -0 0</pose>
          <mass>0.5</mass>
          <inertia>
            <ixx>0.00107917</ixx>
            <ixy>0</ixy>
            <ixz>0</ixz>
            <iyy>0.00107917</iyy>
            <iyz>0</iyz>
            <izz>0.002025</izz>
          </inertia>
        </inertial>
        <collision name='logger-left_wheel_collision'>
          <pose>0 0 0 1.5708 -0 0</pose>
          <geometry>
            <cylinder>
              <length>0.04</length>
              <radius>0.09</radius>
            </cylinder>
          </geometry>
          <surface>
            <contact>
              <ode/>
            </contact>
            <friction>
              <ode>
                <mu>0.99</mu>
                <mu2>0.99</mu2>
              </ode>
              <torsional>
                <ode/>
              </torsional>
            </friction>
            <bounce/>
          </surface>
          <max_contacts>10</max_contacts>
        </collision>
        <visual name='logger-left_wheel_visual'>
          <pose>0 0 0 1.5708 -0 0</pose>
          <geometry>
            <cylinder>
              <length>0.04</length>
              <radius>0.09</radius>
            </cylinder>
          </geometry>
          <material>
            <script>
              <name>Gazebo/Wood</name>
              <uri>file://media/materials/scripts/gazebo.material</uri>
            </script>
          </material>
        </visual>
        <gravity>1</gravity>
        <velocity_decay/>
        <self_collide>0</self_collide>
        <enable_wind>0</enable_wind>
        <kinematic>0</kinematic>
      </link>
      <joint name='logger-chassis2right_wheel' type='revolute'>
        <pose relative_to='logger-chassis'>-0.125 0.125 0 0 -0 0</pose>
        <parent>logger-chassis</parent>
        <child>logger-right_wheel</child>
        <axis>
          <xyz>0 1 0</xyz>
          <limit>
            <lower>-1e+16</lower>
            <upper>1e+16</upper>
          </limit>
          <dynamics>
            <spring_reference>0</spring_reference>
            <spring_stiffness>0</spring_stiffness>
          </dynamics>
        </axis>
      </joint>
      <link name='logger-right_wheel'>
        <pose relative_to='logger-chassis2right_wheel'>0 0 0 0 -0 0</pose>
        <inertial>
          <pose>0 0 0 1.5708 -0 0</pose>
          <mass>0.5</mass>
          <inertia>
            <ixx>0.00107917</ixx>
            <ixy>0</ixy>
            <ixz>0</ixz>
            <iyy>0.00107917</iyy>
            <iyz>0</iyz>
            <izz>0.002025</izz>
          </inertia>
        </inertial>
        <collision name='logger-right_wheel_collision'>
          <pose>0 0 0 1.5708 -0 0</pose>
          <geometry>
            <cylinder>
              <length>0.04</length>
              <radius>0.09</radius>
            </cylinder>
          </geometry>
          <surface>
            <contact>
              <ode/>
            </contact>
            <friction>
              <ode>
                <mu>0.99</mu>
                <mu2>0.99</mu2>
              </ode>
              <torsional>
                <ode/>
              </torsional>
            </friction>
            <bounce/>
          </surface>
          <max_contacts>10</max_contacts>
        </collision>
        <visual name='logger-right_wheel_visual'>
          <pose>0 0 0 1.5708 -0 0</pose>
          <geometry>
            <cylinder>
              <length>0.04</length>
              <radius>0.09</radius>
            </cylinder>
          </geometry>
          <material>
            <script>
              <name>Gazebo/Wood</name>
              <uri>file://media/materials/scripts/gazebo.material</uri>
            </script>
          </material>
        </visual>
        <gravity>1</gravity>
        <velocity_decay/>
        <self_collide>0</self_collide>
        <enable_wind>0</enable_wind>
        <kinematic>0</kinematic>
      </link>
      <static>0</static>
      <plugin name='differential_drive_controller' filename='libgazebo_ros_diff_drive.so'>
        <legacyMode>0</legacyMode>
        <alwaysOn>1</alwaysOn>
        <updateRate>100</updateRate>
        <leftJoint>logger-chassis2left_wheel</leftJoint>
        <rightJoint>logger-chassis2right_wheel</rightJoint>
        <wheelSeparation>0.25</wheelSeparation>
        <wheelDiameter>0.18</wheelDiameter>
        <wheelTorque>1</wheelTorque>
        <commandTopic>logger0/cmd_vel</commandTopic>
        <odometryTopic>odom</odometryTopic>
        <odometryFrame>odom</odometryFrame>
        <robotBaseFrame>logger-chassis</robotBaseFrame>
        <robotNamespace>/</robotNamespace>
      </plugin>
      <pose>-1 0 0.1 0 -0 1.57</pose>
    </model>
    <state world_name='default'>
      <sim_time>31 23000000</sim_time>
      <real_time>31 154255183</real_time>
      <wall_time>1625238303 555603061</wall_time>
      <iterations>31023</iterations>
      <model name='ground_plane'>
        <pose>0 0 0 0 -0 0</pose>
        <scale>1 1 1</scale>
        <link name='link'>
          <pose>0 0 0 0 -0 0</pose>
          <velocity>0 0 0 0 -0 0</velocity>
          <acceleration>0 0 0 0 -0 0</acceleration>
          <wrench>0 0 0 0 -0 0</wrench>
        </link>
      </model>
      <model name='logger0'>
        <pose>-1.00006 0.002675 0.09 0 -0 1.57176</pose>
        <scale>1 1 1</scale>
        <link name='logger-chassis'>
          <pose>-1.00006 0.002675 0.09 0 -0 1.57176</pose>
          <velocity>-8e-06 -0.000695 0.001742 0.013734 3.1e-05 3.2e-05</velocity>
          <acceleration>-0.012941 -1.42575 3.64829 1.15572 0.058369 0.293395</acceleration>
          <wrench>-0.027177 -2.99407 7.66141 0 -0 0</wrench>
        </link>
        <link name='logger-hat'>
          <pose>-1.00006 0.002675 0.19 0 -0 1.57</pose>
          <velocity>-5e-06 -0.002052 0.001734 0.013813 3e-05 0</velocity>
          <acceleration>-0.003812 -5.30871 3.46885 2.49206 0.060635 -3.6e-05</acceleration>
          <wrench>-0.001906 -2.65435 1.73442 0 -0 0</wrench>
        </link>
        <link name='logger-left_wheel'>
          <pose>-0.874936 -0.122206 0.09 5e-06 0.016237 1.57175</pose>
          <velocity>6e-06 -0.000856 -6e-06 0.00992 5.6e-05 -0.001466</velocity>
          <acceleration>0.012084 -1.81479 -0.012285 -1.39032 0.253293 -2.95626</acceleration>
          <wrench>0.006042 -0.907395 -0.006143 0 -0 0</wrench>
        </link>
        <link name='logger-right_wheel'>
          <pose>-1.12494 -0.122445 0.09 -5e-06 0.01565 1.57176</pose>
          <velocity>-8e-06 -0.00086 -6e-06 0.009987 -6.9e-05 0.001576</velocity>
          <acceleration>-0.014499 -1.81631 -0.012024 -1.36085 -0.317972 3.12763</acceleration>
          <wrench>-0.007249 -0.908156 -0.006012 0 -0 0</wrench>
        </link>
      </model>
      <model name='logger1'>
        <pose>0.999943 0.002704 0.089998 0 1.5e-05 1.57178</pose>
        <scale>1 1 1</scale>
        <link name='logger-chassis'>
          <pose>0.999943 0.002704 0.089998 0 1.5e-05 1.57178</pose>
          <velocity>5e-06 0.000795 -0.001742 -0.013722 -3.2e-05 -7e-06</velocity>
          <acceleration>0.01292 1.42535 -3.64851 -1.15714 -0.05906 -0.2934</acceleration>
          <wrench>0.027132 2.99323 -7.66188 0 -0 0</wrench>
        </link>
        <link name='logger-hat'>
          <pose>0.999943 0.002706 0.189998 0 1.5e-05 1.57</pose>
          <velocity>2e-06 0.00215 -0.001734 -0.013801 -3.1e-05 0</velocity>
          <acceleration>0.003693 5.30848 -3.46905 -2.49365 -0.061331 3.2e-05</acceleration>
          <wrench>0.001846 2.65424 -1.73452 0 -0 0</wrench>
        </link>
        <link name='logger-left_wheel'>
          <pose>1.12507 -0.122173 0.09 1.2e-05 0.016346 1.57178</pose>
          <velocity>-5e-06 0.000958 6e-06 -0.011042 -0.000106 0.001491</velocity>
          <acceleration>-0.012131 1.81458 0.012295 1.39135 -0.253718 2.95784</acceleration>
          <wrench>-0.006065 0.907291 0.006147 0 -0 0</wrench>
        </link>
        <link name='logger-right_wheel'>
          <pose>0.875067 -0.122419 0.09 -1.3e-05 0.01576 1.57178</pose>
          <velocity>6e-06 0.000956 5e-06 -0.01103 0.000117 -0.001552</velocity>
          <acceleration>0.014475 1.8161 0.012036 1.3619 0.317309 -3.12928</acceleration>
          <wrench>0.007237 0.90805 0.006018 0 -0 0</wrench>
        </link>
      </model>
      <light name='sun'>
        <pose>0 0 10 0 -0 0</pose>
      </light>
    </state>
  </world>
</sdf>
